<mujoco model="ur5e">
  <compiler autolimits="true" angle="radian"/>
  <option integrator="implicitfast"/>
  <default>
    <default class="/">
      <default class="ur5e">
        <material specular="0.5" shininess="0.25"/>
        <joint axis="0 1 0" range="-6.2831900000000003 6.2831900000000003" armature="0.10000000000000001"/>
        <site group="4" rgba="0.5 0.5 0.5 0.29999999999999999" size="0.001"/>
        <general ctrlrange="-6.2831000000000001 6.2831000000000001" forcerange="-150 150" gaintype="fixed" biastype="affine" gainprm="2000" biasprm="0 -2000 -400"/>
        <default class="size3">
          <default class="size3_limited">
            <joint range="-3.1415000000000002 3.1415000000000002"/>
            <general ctrlrange="-3.1415000000000002 3.1415000000000002"/>
          </default>
        </default>
        <default class="size1">
          <general forcerange="-28 28" gainprm="500" biasprm="0 -500 -100"/>
        </default>
        <default class="visual">
          <geom type="mesh" contype="0" conaffinity="0" group="2"/>
        </default>
        <default class="collision">
          <geom type="capsule" group="3"/>
          <default class="eef_collision">
            <geom type="cylinder"/>
          </default>
        </default>
      </default>
    </default>
    <default class="vacuum_gripper/"/>
  </default>
  <asset>
    <material name="black" class="ur5e" rgba="0.033000000000000002 0.033000000000000002 0.033000000000000002 1"/>
    <material name="jointgray" class="ur5e" rgba="0.27800000000000002 0.27800000000000002 0.27800000000000002 1"/>
    <material name="linkgray" class="ur5e" rgba="0.81999999999999995 0.81999999999999995 0.81999999999999995 1"/>
    <material name="urblue" class="ur5e" rgba="0.48999999999999999 0.67800000000000005 0.80000000000000004 1"/>
    <mesh name="base_0" class="/" file="base_0-5f93152994e0f999174cb75882f556cd760d637d.obj"/>
    <mesh name="base_1" class="/" file="base_1-b3f3b902ea82c2cd8f1eb4e2f17051a77d0b5aca.obj"/>
    <mesh name="shoulder_0" class="/" file="shoulder_0-25635560783dbe95ad2c2d801f7124ef051af0fa.obj"/>
    <mesh name="shoulder_1" class="/" file="shoulder_1-f962752be9057572ca04c7984e63c10cc456d0ff.obj"/>
    <mesh name="shoulder_2" class="/" file="shoulder_2-0c8ec2edec90effe9fa9769c391e0b34b8e326b8.obj"/>
    <mesh name="upperarm_0" class="/" file="upperarm_0-d0095589702d42a94da15a099815e565fc4a53bc.obj"/>
    <mesh name="upperarm_1" class="/" file="upperarm_1-4238cf0fc6ee8840a8b14497d42b5c5169149eaa.obj"/>
    <mesh name="upperarm_2" class="/" file="upperarm_2-2823c8ca17eae0f83c8ddece34935ff90ddf00ff.obj"/>
    <mesh name="upperarm_3" class="/" file="upperarm_3-6894ff569985fd22ce3f5a5113ce3e1e6b698a38.obj"/>
    <mesh name="forearm_0" class="/" file="forearm_0-12f326487f5f3d7b6b47b376292e04d67fba88dd.obj"/>
    <mesh name="forearm_1" class="/" file="forearm_1-8924861122901b845c6a00bcc7d7d6823e878b6e.obj"/>
    <mesh name="forearm_2" class="/" file="forearm_2-d59578ed656d29c4c95f50b52227198afa7a56a0.obj"/>
    <mesh name="forearm_3" class="/" file="forearm_3-c200775ab8a4f4bd1caa22e177a9c08b43d68c62.obj"/>
    <mesh name="wrist1_0" class="/" file="wrist1_0-046c8a7075dd693b4501daf6f622944d9130ab1e.obj"/>
    <mesh name="wrist1_1" class="/" file="wrist1_1-857a385bc0c78c12621e8b23198925c16388212d.obj"/>
    <mesh name="wrist1_2" class="/" file="wrist1_2-b608a06608014b91b7e5e581fea142a762bde488.obj"/>
    <mesh name="wrist2_0" class="/" file="wrist2_0-c4fb307f6b793fcd764f8ece4d79ba597b35ed15.obj"/>
    <mesh name="wrist2_1" class="/" file="wrist2_1-a70236a2d42b0bf1da2e7363b2977ebae9d9859c.obj"/>
    <mesh name="wrist2_2" class="/" file="wrist2_2-752adb14067cdecb847cee843f1938d9b0126a72.obj"/>
    <mesh name="wrist3" class="/" file="wrist3-950944a2ff757dfae2e61bce281f9639ba70efa6.obj"/>
    <mesh name="vacuum_gripper/gripper_mesh" class="vacuum_gripper/" file="vacuum_gripper-b8ba751c400decde48771f5e6970c281853af93c.stl" scale="1 1 1"/>
  </asset>
  <worldbody>
    <light name="spotlight" class="/" mode="targetbodycom" target="wrist_2_link" pos="0 -1 2"/>
    <body name="base" childclass="ur5e" quat="0 0 0 -1">
      <inertial pos="0 0 0" mass="4" diaginertia="0.0044333315599999999 0.0044333315599999999 0.0071999999999999998"/>
      <geom name="//unnamed_geom_0" class="visual" material="black" mesh="base_0"/>
      <geom name="//unnamed_geom_1" class="visual" material="jointgray" mesh="base_1"/>
      <body name="shoulder_link" pos="0 0 0.16300000000000001">
        <inertial pos="0 0 0" mass="3.7000000000000002" diaginertia="0.010267500000000001 0.010267500000000001 0.0066600000000000001"/>
        <joint name="shoulder_pan_joint" class="size3" axis="0 0 1"/>
        <geom name="//unnamed_geom_2" class="visual" material="urblue" mesh="shoulder_0"/>
        <geom name="//unnamed_geom_3" class="visual" material="black" mesh="shoulder_1"/>
        <geom name="//unnamed_geom_4" class="visual" material="jointgray" mesh="shoulder_2"/>
        <geom name="//unnamed_geom_5" class="collision" size="0.059999999999999998 0.059999999999999998" pos="0 0 -0.040000000000000001"/>
        <body name="upper_arm_link" pos="0 0.13800000000000001 0" quat="1 0 1 0">
          <inertial pos="0 0 0.21249999999999999" mass="8.3930000000000007" diaginertia="0.13388600000000001 0.13388600000000001 0.0151074"/>
          <joint name="shoulder_lift_joint" class="size3"/>
          <geom name="//unnamed_geom_6" class="visual" material="linkgray" mesh="upperarm_0"/>
          <geom name="//unnamed_geom_7" class="visual" material="black" mesh="upperarm_1"/>
          <geom name="//unnamed_geom_8" class="visual" material="jointgray" mesh="upperarm_2"/>
          <geom name="//unnamed_geom_9" class="visual" material="urblue" mesh="upperarm_3"/>
          <geom name="//unnamed_geom_10" class="collision" size="0.059999999999999998 0.059999999999999998" pos="0 -0.040000000000000001 0" quat="1 1 0 0"/>
          <geom name="//unnamed_geom_11" class="collision" size="0.050000000000000003 0.20000000000000001" pos="0 0 0.20000000000000001"/>
          <body name="forearm_link" pos="0 -0.13100000000000001 0.42499999999999999">
            <inertial pos="0 0 0.19600000000000001" mass="2.2749999999999999" diaginertia="0.031179599999999998 0.031179599999999998 0.0040949999999999997"/>
            <joint name="elbow_joint" class="size3_limited"/>
            <geom name="//unnamed_geom_12" class="visual" material="urblue" mesh="forearm_0"/>
            <geom name="//unnamed_geom_13" class="visual" material="linkgray" mesh="forearm_1"/>
            <geom name="//unnamed_geom_14" class="visual" material="black" mesh="forearm_2"/>
            <geom name="//unnamed_geom_15" class="visual" material="jointgray" mesh="forearm_3"/>
            <geom name="//unnamed_geom_16" class="collision" size="0.055 0.059999999999999998" pos="0 0.080000000000000002 0" quat="1 1 0 0"/>
            <geom name="//unnamed_geom_17" class="collision" size="0.037999999999999999 0.19" pos="0 0 0.20000000000000001"/>
            <body name="wrist_1_link" pos="0 0 0.39200000000000002" quat="1 0 1 0">
              <inertial pos="0 0.127 0" mass="1.2190000000000001" diaginertia="0.0025598999999999999 0.0025598999999999999 0.0021941999999999999"/>
              <joint name="wrist_1_joint" class="size1"/>
              <geom name="//unnamed_geom_18" class="visual" material="black" mesh="wrist1_0"/>
              <geom name="//unnamed_geom_19" class="visual" material="urblue" mesh="wrist1_1"/>
              <geom name="//unnamed_geom_20" class="visual" material="jointgray" mesh="wrist1_2"/>
              <geom name="//unnamed_geom_21" class="collision" size="0.040000000000000001 0.070000000000000007" pos="0 0.050000000000000003 0" quat="1 1 0 0"/>
              <body name="wrist_2_link" pos="0 0.127 0">
                <inertial pos="0 0 0.10000000000000001" mass="1.2190000000000001" diaginertia="0.0025598999999999999 0.0025598999999999999 0.0021941999999999999"/>
                <joint name="wrist_2_joint" class="size1" axis="0 0 1"/>
                <geom name="//unnamed_geom_22" class="visual" material="black" mesh="wrist2_0"/>
                <geom name="//unnamed_geom_23" class="visual" material="urblue" mesh="wrist2_1"/>
                <geom name="//unnamed_geom_24" class="visual" material="jointgray" mesh="wrist2_2"/>
                <geom name="//unnamed_geom_25" class="collision" size="0.040000000000000001 0.059999999999999998" pos="0 0 0.040000000000000001"/>
                <geom name="//unnamed_geom_26" class="collision" size="0.040000000000000001 0.040000000000000001" pos="0 0.02 0.10000000000000001" quat="1 1 0 0"/>
                <body name="wrist_3_link" pos="0 0 0.10000000000000001">
                  <inertial pos="0 0.077168299999999995 0" quat="1 0 0 1" mass="0.18890000000000001" diaginertia="0.00013213400000000001 9.90863e-05 9.90863e-05"/>
                  <joint name="wrist_3_joint" class="size1"/>
                  <geom name="//unnamed_geom_27" class="visual" material="linkgray" mesh="wrist3"/>
                  <geom name="//unnamed_geom_28" class="eef_collision" size="0.040000000000000001 0.02" pos="0 0.080000000000000002 0" quat="1 1 0 0"/>
                  <site name="attachment_site" pos="0 0.10000000000000001 0" quat="-1 1 0 0"/>
                  <body pos="0 0.10000000000000001 0" quat="-1 1 0 0" name="vacuum_gripper/">
                    <body name="vacuum_gripper/suction_base_link">
                      <geom name="vacuum_gripper//unnamed_geom_0" class="vacuum_gripper/" type="mesh" contype="0" conaffinity="0" rgba="0.69999999999999996 0.69999999999999996 0.69999999999999996 1" mass="0.5" mesh="vacuum_gripper/gripper_mesh"/>
                      <geom name="vacuum_gripper//unnamed_geom_1" class="vacuum_gripper/" type="cylinder" size="0.040000000000000001 0.050000000000000003" rgba="1 0 0 0" mass="0" pos="0 0 0.050000000000000003"/>
                      <body name="vacuum_gripper/tcp_link" pos="0 0 0.12">
                        <site name="vacuum_gripper/tcp_site" class="vacuum_gripper/" rgba="1 0 0 1" size="0.0050000000000000001"/>
                      </body>
                    </body>
                  </body>
                </body>
              </body>
            </body>
          </body>
        </body>
      </body>
    </body>
  </worldbody>
  <actuator>
    <general name="shoulder_pan" class="size3" joint="shoulder_pan_joint"/>
    <general name="shoulder_lift" class="size3" joint="shoulder_lift_joint"/>
    <general name="elbow" class="size3_limited" joint="elbow_joint"/>
    <general name="wrist_1" class="size1" joint="wrist_1_joint"/>
    <general name="wrist_2" class="size1" joint="wrist_2_joint"/>
    <general name="wrist_3" class="size1" joint="wrist_3_joint"/>
  </actuator>
  <keyframe>
    <key name="home" qpos="-1.5708 -1.5708 1.5708 -1.5708 -1.5708 0" ctrl="-1.5708 -1.5708 1.5708 -1.5708 -1.5708 0"/>
  </keyframe>
</mujoco>
